Workbook

Sheet Dashboard
B2: GREENSIDE VILLAS — DIGITAL MARKETING DASHBOARD
B4: Weekly tracking across Facebook, Instagram, Website, and Airbnb — Jan 2025 to Jul 2026 · Live formulas, updates automatically
B6: TOTAL REACH (Facebook + Instagram) | E6: TOTAL ENGAGEMENT (Facebook + Instagram) | H6: WEBSITE VISITORS (cumulative) | K6: AIRBNB BOOKINGS | N6: AIRBNB REVENUE | Q6: AVG. OCCUPANCY RATE
B8: =SUM(Facebook!F:F)+SUM(Instagram!F:F) -> 128690 | E8: =SUM(Facebook!E:E)+SUM(Instagram!E:E) -> 5091 | H8: =SUM(Website!B:B) -> 167230 | K8: =SUM(Airbnb!E:E) -> 9 | N8: =SUM(Airbnb!G:G) -> 3198 | Q8: =AVERAGE(Airbnb!H:H) -> 0.063490076
B12: MARKETING FUNNEL (cumulative, all channels)
B13: Stage | C13: Volume
B14: Awareness (Reach) | C14: =SUM(Facebook!F:F)+SUM(Instagram!F:F) -> 128690
B15: Interest (Engagement) | C15: =SUM(Facebook!E:E)+SUM(Instagram!E:E) -> 5091
B16: Intent (Website Visitors + Airbnb Views) | C16: =SUM(Website!B:B)+SUM(Airbnb!C:C) -> 167972
B17: Conversion (Airbnb Bookings) | C17: =SUM(Airbnb!E:E) -> 9
B30: WEBSITE TRAFFIC TREND | L30: AIRBNB BOOKINGS & REVENUE TREND
B49: FACEBOOK vs INSTAGRAM — REACH TREND
B69: INTERACTIVE CHANNEL EXPLORER
B70: Select a channel: | C70: Facebook
B72: Week | C72: Primary Metric (Reach / Visitors / Views) | D72: Secondary Metric (Engagement / Conversions / Bookings)
B73: =Facebook!A3 -> 45660 | C73: =IF($C$70="Facebook",IFERROR(INDEX(Facebook!$F:$F,MATCH($B73,Facebook!$A:$A,0)),""),IF($C$70="Instagram",IFERROR(INDEX(Instagram!$F:$F,MATCH($B73,Instagram!$A:$A,0)),""),IF($C$70="Website",IFERROR(INDEX(Website!$B:$B,MATCH($B73,Website!$A:$A,0)),""),IF($C$70="Airbnb",IFERROR(INDEX(Airbnb!$C:$C,MATCH($B73,Airbnb!$A:$A,0)),""),"")))) -> 219 | D73: =IF($C$70="Facebook",IFERROR(INDEX(Facebook!$E:$E,MATCH($B73,Facebook!$A:$A,0)),""),IF($C$70="Instagram",IFERROR(INDEX(Instagram!$E:$E,MATCH($B73,Instagram!$A:$A,0)),""),IF($C$70="Website",IFERROR(INDEX(Website!$F:$F,MATCH($B73,Website!$A:$A,0)),""),IF($C$70="Airbnb",IFERROR(INDEX(Airbnb!$E:$E,MATCH($B73,Airbnb!$A:$A,0)),""),"")))) -> 11
B74: =Facebook!A4 -> 45667 | C74: =IF($C$70="Facebook",IFERROR(INDEX(Facebook!$F:$F,MATCH($B74,Facebook!$A:$A,0)),""),IF($C$70="Instagram",IFERROR(INDEX(Instagram!$F:$F,MATCH($B74,Instagram!$A:$A,0)),""),IF($C$70="Website",IFERROR(INDEX(Website!$B:$B,MATCH($B74,Website!$A:$A,0)),""),IF($C$70="Airbnb",IFERROR(INDEX(Airbnb!$C:$C,MATCH($B74,Airbnb!$A:$A,0)),""),"")))) -> 198 | D74: =IF($C$70="Facebook",IFERROR(INDEX(Facebook!$E:$E,MATCH($B74,Facebook!$A:$A,0)),""),IF($C$70="Instagram",IFERROR(INDEX(Instagram!$E:$E,MATCH($B74,Instagram!$A:$A,0)),""),IF($C$70="Website",IFERROR(INDEX(Website!$F:$F,MATCH($B74,Website!$A:$A,0)),""),IF($C$70="Airbnb",IFERROR(INDEX(Airbnb!$E:$E,MATCH($B74,Airbnb!$A:$A,0)),""),"")))) -> 9
B75: =Facebook!A5 -> 45674 | C75: =IF($C$70="Facebook",IFERROR(INDEX(Facebook!$F:$F,MATCH($B75,Facebook!$A:$A,0)),""),IF($C$70="Instagram",IFERROR(INDEX(Instagram!$F:$F,MATCH($B75,Instagram!$A:$A,0)),""),IF($C$70="Website",IFERROR(INDEX(Website!$B:$B,MATCH($B75,Website!$A:$A,0)),""),IF($C$70="Airbnb",IFERROR(INDEX(Airbnb!$C:$C,MATCH($B75,Airbnb!$A:$A,0)),""),"")))) -> 199 | D75: =IF($C$70="Facebook",IFERROR(INDEX(Facebook!$E:$E,MATCH($B75,Facebook!$A:$A,0)),""),IF($C$70="Instagram",IFERROR(INDEX(Instagram!$E:$E,MATCH($B75,Instagram!$A:$A,0)),""),IF($C$70="Website",IFERROR(INDEX(Website!$F:$F,MATCH($B75,Website!$A:$A,0)),""),IF($C$70="Airbnb",IFERROR(INDEX(Airbnb!$E:$E,MATCH($B75,Airbnb!$A:$A,0)),""),"")))) -> 9
B76: =Facebook!A6 -> 45681 | C76: =IF($C$70="Facebook",IFERROR(INDEX(Facebook!$F:$F,MATCH($B76,Facebook!$A:$A,0)),""),IF($C$70="Instagram",IFERROR(INDEX(Instagram!$F:$F,MATCH($B76,Instagram!$A:$A,0)),""),IF($C$70="Website",IFERROR(INDEX(Website!$B:$B,MATCH($B76,Website!$A:$A,0)),""),IF($C$70="Airbnb",IFERROR(INDEX(Airbnb!$C:$C,MATCH($B76,Airbnb!$A:$A,0)),""),"")))) -> 2783 | D76: =IF($C$70="Facebook",IFERROR(INDEX(Facebook!$E:$E,MATCH($B76,Facebook!$A:$A,0)),""),IF($C$70="Instagram",IFERROR(INDEX(Instagram!$E:$E,MATCH($B76,Instagram!$A:$A,0)),""),IF($C$70="Website",IFERROR(INDEX(Website!$F:$F,MATCH($B76,Website!$A:$A,0)),""),IF($C$70="Airbnb",IFERROR(INDEX(Airbnb!$E:$E,MATCH($B76,Airbnb!$A:$A,0)),""),"")))) -> 688
B77: =Facebook!A7 -> 45688 | C77: =IF($C$70="Facebook",IFERROR(INDEX(Facebook!$F:$F,MATCH($B77,Facebook!$A:$A,0)),""),IF($C$70="Instagram",IFERROR(INDEX(Instagram!$F:$F,MATCH($B77,Instagram!$A:$A,0)),""),IF($C$70="Website",IFERROR(INDEX(Website!$B:$B,MATCH($B77,Website!$A:$A,0)),""),IF($C$70="Airbnb",IFERROR(INDEX(Airbnb!$C:$C,MATCH($B77,Airbnb!$A:$A,0)),""),"")))) -> 8700 | D77: =IF($C$70="Facebook",IFERROR(INDEX(Facebook!$E:$E,MATCH($B77,Facebook!$A:$A,0)),""),IF($C$70="Instagram",IFERROR(INDEX(Instagram!$E:$E,MATCH($B77,Instagram!$A:$A,0)),""),IF($C$70="Website",IFERROR(INDEX(Website!$F:$F,MATCH($B77,Website!$A:$A,0)),""),IF($C$70="Airbnb",IFERROR(INDEX(Airbnb!$E:$E,MATCH($B77,Airbnb!$A:$A,0)),""),"")))) -> 1291
B78: =Facebook!A8 -> 45695 | C78: =IF($C$70="Facebook",IFERROR(INDEX(Facebook!$F:$F,MATCH($B78,Facebook!$A:$A,0)),""),IF($C$70="Instagram",IFERROR(INDEX(Instagram!$F:$F,MATCH($B78,Instagram!$A:$A,0)),""),IF($C$70="Website",IFERROR(INDEX(Website!$B:$B,MATCH($B78,Website!$A:$A,0)),""),IF($C$70="Airbnb",IFERROR(INDEX(Airbnb!$C:$C,MATCH($B78,Airbnb!$A:$A,0)),""),"")))) -> 147 | D78: =IF($C$70="Facebook",IFERROR(INDEX(Facebook!$E:$E,MATCH($B78,Facebook!$A:$A,0)),""),IF($C$70="Instagram",IFERROR(INDEX(Instagram!$E:$E,MATCH($B78,Instagram!$A:$A,0)),""),IF($C$70="Website",IFERROR(INDEX(Website!$F:$F,MATCH($B78,Website!$A:$A,0)),""),IF($C$70="Airbnb",IFERROR(INDEX(Airbnb!$E:$E,MATCH($B78,Airbnb!$A:$A,0)),""),"")))) -> 4
B79: =Facebook!A9 -> 45702 | C79: =IF($C$70="Facebook",IFERROR(INDEX(Facebook!$F:$F,MATCH($B79,Facebook!$A:$A,0)),""),IF($C$70="Instagram",IFERROR(INDEX(Instagram!$F:$F,MATCH($B79,Instagram!$A:$A,0)),""),IF($C$70="Website",IFERROR(INDEX(Website!$B:$B,MATCH($B79,Website!$A:$A,0)),""),IF($C$70="Airbnb",IFERROR(INDEX(Airbnb!$C:$C,MATCH($B79,Airbnb!$A:$A,0)),""),"")))) -> 100 | D79: =IF($C$70="Facebook",IFERROR(INDEX(Facebook!$E:$E,MATCH($B79,Facebook!$A:$A,0)),""),IF($C$70="Instagram",IFERROR(INDEX(Instagram!$E:$E,MATCH($B79,Instagram!$A:$A,0)),""),IF($C$70="Website",IFERROR(INDEX(Website!$F:$F,MATCH($B79,Website!$A:$A,0)),""),IF($C$70="Airbnb",IFERROR(INDEX(Airbnb!$E:$E,MATCH($B79,Airbnb!$A:$A,0)),""),"")))) -> 2
B80: =Facebook!A10 -> 45709 | C80: =IF($C$70="Facebook",IFERROR(INDEX(Facebook!$F:$F,MATCH($B80,Facebook!$A:$A,0)),""),IF($C$70="Instagram",IFERROR(INDEX(Instagram!$F:$F,MATCH($B80,Instagram!$A:$A,0)),""),IF($C$70="Website",IFERROR(INDEX(Website!$B:$B,MATCH($B80,Website!$A:$A,0)),""),IF($C$70="Airbnb",IFERROR(INDEX(Airbnb!$C:$C,MATCH($B80,Airbnb!$A:$A,0)),""),"")))) -> 26 | D80: =IF($C$70="Facebook",IFERROR(INDEX(Facebook!$E:$E,MATCH($B80,Facebook!$A:$A,0)),""),IF($C$70="Instagram",IFERROR(INDEX(Instagram!$E:$E,MATCH($B80,Instagram!$A:$A,0)),""),IF($C$70="Website",IFERROR(INDEX(Website!$F:$F,MATCH($B80,Website!$A:$A,0)),""),IF($C$70="Airbnb",IFERROR(INDEX(Airbnb!$E:$E,MATCH($B80,Airbnb!$A:$A,0)),""),"")))) -> 4
B81: =Facebook!A11 -> 45716 | C81: =IF($C$70="Facebook",IFERROR(INDEX(Facebook!$F:$F,MATCH($B81,Facebook!$A:$A,0)),""),IF($C$70="Instagram",IFERROR(INDEX(Instagram!$F:$F,MATCH($B81,Instagram!$A:$A,0)),""),IF($C$70="Website",IFERROR(INDEX(Website!$B:$B,MATCH($B81,Website!$A:$A,0)),""),IF($C$70="Airbnb",IFERROR(INDEX(Airbnb!$C:$C,MATCH($B81,Airbnb!$A:$A,0)),""),"")))) -> 10 | D81: =IF($C$70="Facebook",IFERROR(INDEX(Facebook!$E:$E,MATCH($B81,Facebook!$A:$A,0)),""),IF($C$70="Instagram",IFERROR(INDEX(Instagram!$E:$E,MATCH($B81,Instagram!$A:$A,0)),""),IF($C$70="Website",IFERROR(INDEX(Website!$F:$F,MATCH($B81,Website!$A:$A,0)),""),IF($C$70="Airbnb",IFERROR(INDEX(Airbnb!$E:$E,MATCH($B81,Airbnb!$A:$A,0)),""),"")))) -> 2
B82: =Facebook!A12 -> 45723 | C82: =IF($C$70="Facebook",IFERROR(INDEX(Facebook!$F:$F,MATCH($B82,Facebook!$A:$A,0)),""),IF($C$70="Instagram",IFERROR(INDEX(Instagram!$F:$F,MATCH($B82,Instagram!$A:$A,0)),""),IF($C$70="Website",IFERROR(INDEX(Website!$B:$B,MATCH($B82,Website!$A:$A,0)),""),IF($C$70="Airbnb",IFERROR(INDEX(Airbnb!$C:$C,MATCH($B82,Airbnb!$A:$A,0)),""),"")))) -> 5 | D82: =IF($C$70="Facebook",IFERROR(INDEX(Facebook!$E:$E,MATCH($B82,Facebook!$A:$A,0)),""),IF($C$70="Instagram",IFERROR(INDEX(Instagram!$E:$E,MATCH($B82,Instagram!$A:$A,0)),""),IF($C$70="Website",IFERROR(INDEX(Website!$F:$F,MATCH($B82,Website!$A:$A,0)),""),IF($C$70="Airbnb",IFERROR(INDEX(Airbnb!$E:$E,MATCH($B82,Airbnb!$A:$A,0)),""),"")))) -> 3
B83: =Facebook!A13 -> 45730 | C83: =IF($C$70="Facebook",IFERROR(INDEX(Facebook!$F:$F,MATCH($B83,Facebook!$A:$A,0)),""),IF($C$70="Instagram",IFERROR(INDEX(Instagram!$F:$F,MATCH($B83,Instagram!$A:$A,0)),""),IF($C$70="Website",IFERROR(INDEX(Website!$B:$B,MATCH($B83,Website!$A:$A,0)),""),IF($C$70="Airbnb",IFERROR(INDEX(Airbnb!$C:$C,MATCH($B83,Airbnb!$A:$A,0)),""),"")))) -> 101 | D83: =IF($C$70="Facebook",IFERROR(INDEX(Facebook!$E:$E,MATCH($B83,Facebook!$A:$A,0)),""),IF($C$70="Instagram",IFERROR(INDEX(Instagram!$E:$E,MATCH($B83,Instagram!$A:$A,0)),""),IF($C$70="Website",IFERROR(INDEX(Website!$F:$F,MATCH($B83,Website!$A:$A,0)),""),IF($C$70="Airbnb",IFERROR(INDEX(Airbnb!$E:$E,MATCH($B83,Airbnb!$A:$A,0)),""),"")))) -> 2
B84: =Facebook!A14 -> 45737 | C84: =IF($C$70="Facebook",IFERROR(INDEX(Facebook!$F:$F,MATCH($B84,Facebook!$A:$A,0)),""),IF($C$70="Instagram",IFERROR(INDEX(Instagram!$F:$F,MATCH($B84,Instagram!$A:$A,0)),""),IF($C$70="Website",IFERROR(INDEX(Website!$B:$B,MATCH($B84,Website!$A:$A,0)),""),IF($C$70="Airbnb",IFERROR(INDEX(Airbnb!$C:$C,MATCH($B84,Airbnb!$A:$A,0)),""),"")))) -> 1164 | D84: =IF($C$70="Facebook",IFERROR(INDEX(Facebook!$E:$E,MATCH($B84,Facebook!$A:$A,0)),""),IF($C$70="Instagram",IFERROR(INDEX(Instagram!$E:$E,MATCH($B84,Instagram!$A:$A,0)),""),IF($C$70="Website",IFERROR(INDEX(Website!$F:$F,MATCH($B84,Website!$A:$A,0)),""),IF($C$70="Airbnb",IFERROR(INDEX(Airbnb!$E:$E,MATCH($B84,Airbnb!$A:$A,0)),""),"")))) -> 17
... B229: =Facebook!A159 -> 46752 | C229: =IF($C$70="Facebook",IFERROR(INDEX(Facebook!$F:$F,MATCH($B229,Facebook!$A:$A,0)),""),IF($C$70="Instagram",IFERROR(INDEX(Instagram!$F:$F,MATCH($B229,Instagram!$A:$A,0)),""),IF($C$70="Website",IFERROR(INDEX(Website!$B:$B,MATCH($B229,Website!$A:$A,0)),""),IF($C$70="Airbnb",IFERROR(INDEX(Airbnb!$C:$C,MATCH($B229,Airbnb!$A:$A,0)),""),"")))) -> 0 | D229: =IF($C$70="Facebook",IFERROR(INDEX(Facebook!$E:$E,MATCH($B229,Facebook!$A:$A,0)),""),IF($C$70="Instagram",IFERROR(INDEX(Instagram!$E:$E,MATCH($B229,Instagram!$A:$A,0)),""),IF($C$70="Website",IFERROR(INDEX(Website!$F:$F,MATCH($B229,Website!$A:$A,0)),""),IF($C$70="Airbnb",IFERROR(INDEX(Airbnb!$E:$E,MATCH($B229,Airbnb!$A:$A,0)),""),"")))) -> 0

Sheet Summary
A1: Summary — Automatic Weekly Roll-Up (pulls live from Facebook, Instagram, Website & Airbnb tabs)
A3: Week | B3: FB Reach | C3: IG Reach | D3: Total Awareness (Reach) | E3: FB Engagement | F3: IG Engagement | G3: Total Interest (Engagement) | H3: Website Visitors | I3: Airbnb Views | J3: Total Intent | K3: Airbnb Inquiries | L3: Airbnb Bookings (Conversions) | M3: Airbnb Revenue ($)
A4: =Facebook!A3 -> 45660 | B4: =IFERROR(INDEX(Facebook!$F:$F,MATCH($A4,Facebook!$A:$A,0)),0) -> 219 | C4: =IFERROR(INDEX(Instagram!$F:$F,MATCH($A4,Instagram!$A:$A,0)),0) -> 157 | D4: =B4+C4 -> 376 | E4: =IFERROR(INDEX(Facebook!$E:$E,MATCH($A4,Facebook!$A:$A,0)),0) -> 11 | F4: =IFERROR(INDEX(Instagram!$E:$E,MATCH($A4,Instagram!$A:$A,0)),0) -> 6 | G4: =E4+F4 -> 17 | H4: =IFERROR(INDEX(Website!$B:$B,MATCH($A4,Website!$A:$A,0)),0) -> 120 | I4: =IFERROR(INDEX(Airbnb!$C:$C,MATCH($A4,Airbnb!$A:$A,0)),0) -> 11 | J4: =H4+I4 -> 131 | K4: =IFERROR(INDEX(Airbnb!$D:$D,MATCH($A4,Airbnb!$A:$A,0)),0) -> 0 | L4: =IFERROR(INDEX(Airbnb!$E:$E,MATCH($A4,Airbnb!$A:$A,0)),0) -> 0 | M4: =IFERROR(INDEX(Airbnb!$G:$G,MATCH($A4,Airbnb!$A:$A,0)),0) -> 0
A5: =Facebook!A4 -> 45667 | B5: =IFERROR(INDEX(Facebook!$F:$F,MATCH($A5,Facebook!$A:$A,0)),0) -> 198 | C5: =IFERROR(INDEX(Instagram!$F:$F,MATCH($A5,Instagram!$A:$A,0)),0) -> 42 | D5: =B5+C5 -> 240 | E5: =IFERROR(INDEX(Facebook!$E:$E,MATCH($A5,Facebook!$A:$A,0)),0) -> 9 | F5: =IFERROR(INDEX(Instagram!$E:$E,MATCH($A5,Instagram!$A:$A,0)),0) -> 6 | G5: =E5+F5 -> 15 | H5: =IFERROR(INDEX(Website!$B:$B,MATCH($A5,Website!$A:$A,0)),0) -> 180 | I5: =IFERROR(INDEX(Airbnb!$C:$C,MATCH($A5,Airbnb!$A:$A,0)),0) -> 12 | J5: =H5+I5 -> 192 | K5: =IFERROR(INDEX(Airbnb!$D:$D,MATCH($A5,Airbnb!$A:$A,0)),0) -> 0 | L5: =IFERROR(INDEX(Airbnb!$E:$E,MATCH($A5,Airbnb!$A:$A,0)),0) -> 0 | M5: =IFERROR(INDEX(Airbnb!$G:$G,MATCH($A5,Airbnb!$A:$A,0)),0) -> 0
A6: =Facebook!A5 -> 45674 | B6: =IFERROR(INDEX(Facebook!$F:$F,MATCH($A6,Facebook!$A:$A,0)),0) -> 199 | C6: =IFERROR(INDEX(Instagram!$F:$F,MATCH($A6,Instagram!$A:$A,0)),0) -> 36 | D6: =B6+C6 -> 235 | E6: =IFERROR(INDEX(Facebook!$E:$E,MATCH($A6,Facebook!$A:$A,0)),0) -> 9 | F6: =IFERROR(INDEX(Instagram!$E:$E,MATCH($A6,Instagram!$A:$A,0)),0) -> 6 | G6: =E6+F6 -> 15 | H6: =IFERROR(INDEX(Website!$B:$B,MATCH($A6,Website!$A:$A,0)),0) -> 200 | I6: =IFERROR(INDEX(Airbnb!$C:$C,MATCH($A6,Airbnb!$A:$A,0)),0) -> 10 | J6: =H6+I6 -> 210 | K6: =IFERROR(INDEX(Airbnb!$D:$D,MATCH($A6,Airbnb!$A:$A,0)),0) -> 0 | L6: =IFERROR(INDEX(Airbnb!$E:$E,MATCH($A6,Airbnb!$A:$A,0)),0) -> 0 | M6: =IFERROR(INDEX(Airbnb!$G:$G,MATCH($A6,Airbnb!$A:$A,0)),0) -> 0
A7: =Facebook!A6 -> 45681 | B7: =IFERROR(INDEX(Facebook!$F:$F,MATCH($A7,Facebook!$A:$A,0)),0) -> 2783 | C7: =IFERROR(INDEX(Instagram!$F:$F,MATCH($A7,Instagram!$A:$A,0)),0) -> 280 | D7: =B7+C7 -> 3063 | E7: =IFERROR(INDEX(Facebook!$E:$E,MATCH($A7,Facebook!$A:$A,0)),0) -> 688 | F7: =IFERROR(INDEX(Instagram!$E:$E,MATCH($A7,Instagram!$A:$A,0)),0) -> 7 | G7: =E7+F7 -> 695 | H7: =IFERROR(INDEX(Website!$B:$B,MATCH($A7,Website!$A:$A,0)),0) -> 230 | I7: =IFERROR(INDEX(Airbnb!$C:$C,MATCH($A7,Airbnb!$A:$A,0)),0) -> 12 | J7: =H7+I7 -> 242 | K7: =IFERROR(INDEX(Airbnb!$D:$D,MATCH($A7,Airbnb!$A:$A,0)),0) -> 0 | L7: =IFERROR(INDEX(Airbnb!$E:$E,MATCH($A7,Airbnb!$A:$A,0)),0) -> 0 | M7: =IFERROR(INDEX(Airbnb!$G:$G,MATCH($A7,Airbnb!$A:$A,0)),0) -> 0
A8: =Facebook!A7 -> 45688 | B8: =IFERROR(INDEX(Facebook!$F:$F,MATCH($A8,Facebook!$A:$A,0)),0) -> 8700 | C8: =IFERROR(INDEX(Instagram!$F:$F,MATCH($A8,Instagram!$A:$A,0)),0) -> 100500 | D8: =B8+C8 -> 109200 | E8: =IFERROR(INDEX(Facebook!$E:$E,MATCH($A8,Facebook!$A:$A,0)),0) -> 1291 | F8: =IFERROR(INDEX(Instagram!$E:$E,MATCH($A8,Instagram!$A:$A,0)),0) -> 146 | G8: =E8+F8 -> 1437 | H8: =IFERROR(INDEX(Website!$B:$B,MATCH($A8,Website!$A:$A,0)),0) -> 250 | I8: =IFERROR(INDEX(Airbnb!$C:$C,MATCH($A8,Airbnb!$A:$A,0)),0) -> 11 | J8: =H8+I8 -> 261 | K8: =IFERROR(INDEX(Airbnb!$D:$D,MATCH($A8,Airbnb!$A:$A,0)),0) -> 0 | L8: =IFERROR(INDEX(Airbnb!$E:$E,MATCH($A8,Airbnb!$A:$A,0)),0) -> 0 | M8: =IFERROR(INDEX(Airbnb!$G:$G,MATCH($A8,Airbnb!$A:$A,0)),0) -> 0
A9: =Facebook!A8 -> 45695 | B9: =IFERROR(INDEX(Facebook!$F:$F,MATCH($A9,Facebook!$A:$A,0)),0) -> 147 | C9: =IFERROR(INDEX(Instagram!$F:$F,MATCH($A9,Instagram!$A:$A,0)),0) -> 359 | D9: =B9+C9 -> 506 | E9: =IFERROR(INDEX(Facebook!$E:$E,MATCH($A9,Facebook!$A:$A,0)),0) -> 4 | F9: =IFERROR(INDEX(Instagram!$E:$E,MATCH($A9,Instagram!$A:$A,0)),0) -> 3 | G9: =E9+F9 -> 7 | H9: =IFERROR(INDEX(Website!$B:$B,MATCH($A9,Website!$A:$A,0)),0) -> 280 | I9: =IFERROR(INDEX(Airbnb!$C:$C,MATCH($A9,Airbnb!$A:$A,0)),0) -> 12 | J9: =H9+I9 -> 292 | K9: =IFERROR(INDEX(Airbnb!$D:$D,MATCH($A9,Airbnb!$A:$A,0)),0) -> 0 | L9: =IFERROR(INDEX(Airbnb!$E:$E,MATCH($A9,Airbnb!$A:$A,0)),0) -> 0 | M9: =IFERROR(INDEX(Airbnb!$G:$G,MATCH($A9,Airbnb!$A:$A,0)),0) -> 0
A10: =Facebook!A9 -> 45702 | B10: =IFERROR(INDEX(Facebook!$F:$F,MATCH($A10,Facebook!$A:$A,0)),0) -> 100 | C10: =IFERROR(INDEX(Instagram!$F:$F,MATCH($A10,Instagram!$A:$A,0)),0) -> 158 | D10: =B10+C10 -> 258 | E10: =IFERROR(INDEX(Facebook!$E:$E,MATCH($A10,Facebook!$A:$A,0)),0) -> 2 | F10: =IFERROR(INDEX(Instagram!$E:$E,MATCH($A10,Instagram!$A:$A,0)),0) -> 1 | G10: =E10+F10 -> 3 | H10: =IFERROR(INDEX(Website!$B:$B,MATCH($A10,Website!$A:$A,0)),0) -> 350 | I10: =IFERROR(INDEX(Airbnb!$C:$C,MATCH($A10,Airbnb!$A:$A,0)),0) -> 10 | J10: =H10+I10 -> 360 | K10: =IFERROR(INDEX(Airbnb!$D:$D,MATCH($A10,Airbnb!$A:$A,0)),0) -> 1 | L10: =IFERROR(INDEX(Airbnb!$E:$E,MATCH($A10,Airbnb!$A:$A,0)),0) -> 0 | M10: =IFERROR(INDEX(Airbnb!$G:$G,MATCH($A10,Airbnb!$A:$A,0)),0) -> 0
A11: =Facebook!A10 -> 45709 | B11: =IFERROR(INDEX(Facebook!$F:$F,MATCH($A11,Facebook!$A:$A,0)),0) -> 26 | C11: =IFERROR(INDEX(Instagram!$F:$F,MATCH($A11,Instagram!$A:$A,0)),0) -> 73 | D11: =B11+C11 -> 99 | E11: =IFERROR(INDEX(Facebook!$E:$E,MATCH($A11,Facebook!$A:$A,0)),0) -> 4 | F11: =IFERROR(INDEX(Instagram!$E:$E,MATCH($A11,Instagram!$A:$A,0)),0) -> 1 | G11: =E11+F11 -> 5 | H11: =IFERROR(INDEX(Website!$B:$B,MATCH($A11,Website!$A:$A,0)),0) -> 400 | I11: =IFERROR(INDEX(Airbnb!$C:$C,MATCH($A11,Airbnb!$A:$A,0)),0) -> 9 | J11: =H11+I11 -> 409 | K11: =IFERROR(INDEX(Airbnb!$D:$D,MATCH($A11,Airbnb!$A:$A,0)),0) -> 0 | L11: =IFERROR(INDEX(Airbnb!$E:$E,MATCH($A11,Airbnb!$A:$A,0)),0) -> 0 | M11: =IFERROR(INDEX(Airbnb!$G:$G,MATCH($A11,Airbnb!$A:$A,0)),0) -> 0
A12: =Facebook!A11 -> 45716 | B12: =IFERROR(INDEX(Facebook!$F:$F,MATCH($A12,Facebook!$A:$A,0)),0) -> 10 | C12: =IFERROR(INDEX(Instagram!$F:$F,MATCH($A12,Instagram!$A:$A,0)),0) -> 38 | D12: =B12+C12 -> 48 | E12: =IFERROR(INDEX(Facebook!$E:$E,MATCH($A12,Facebook!$A:$A,0)),0) -> 2 | F12: =IFERROR(INDEX(Instagram!$E:$E,MATCH($A12,Instagram!$A:$A,0)),0) -> 1 | G12: =E12+F12 -> 3 | H12: =IFERROR(INDEX(Website!$B:$B,MATCH($A12,Website!$A:$A,0)),0) -> 450 | I12: =IFERROR(INDEX(Airbnb!$C:$C,MATCH($A12,Airbnb!$A:$A,0)),0) -> 5 | J12: =H12+I12 -> 455 | K12: =IFERROR(INDEX(Airbnb!$D:$D,MATCH($A12,Airbnb!$A:$A,0)),0) -> 0 | L12: =IFERROR(INDEX(Airbnb!$E:$E,MATCH($A12,Airbnb!$A:$A,0)),0) -> 0 | M12: =IFERROR(INDEX(Airbnb!$G:$G,MATCH($A12,Airbnb!$A:$A,0)),0) -> 0
A13: =Facebook!A12 -> 45723 | B13: =IFERROR(INDEX(Facebook!$F:$F,MATCH($A13,Facebook!$A:$A,0)),0) -> 5 | C13: =IFERROR(INDEX(Instagram!$F:$F,MATCH($A13,Instagram!$A:$A,0)),0) -> 30 | D13: =B13+C13 -> 35 | E13: =IFERROR(INDEX(Facebook!$E:$E,MATCH($A13,Facebook!$A:$A,0)),0) -> 3 | F13: =IFERROR(INDEX(Instagram!$E:$E,MATCH($A13,Instagram!$A:$A,0)),0) -> 1 | G13: =E13+F13 -> 4 | H13: =IFERROR(INDEX(Website!$B:$B,MATCH($A13,Website!$A:$A,0)),0) -> 550 | I13: =IFERROR(INDEX(Airbnb!$C:$C,MATCH($A13,Airbnb!$A:$A,0)),0) -> 7 | J13: =H13+I13 -> 557 | K13: =IFERROR(INDEX(Airbnb!$D:$D,MATCH($A13,Airbnb!$A:$A,0)),0) -> 0 | L13: =IFERROR(INDEX(Airbnb!$E:$E,MATCH($A13,Airbnb!$A:$A,0)),0) -> 0 | M13: =IFERROR(INDEX(Airbnb!$G:$G,MATCH($A13,Airbnb!$A:$A,0)),0) -> 0
A14: =Facebook!A13 -> 45730 | B14: =IFERROR(INDEX(Facebook!$F:$F,MATCH($A14,Facebook!$A:$A,0)),0) -> 101 | C14: =IFERROR(INDEX(Instagram!$F:$F,MATCH($A14,Instagram!$A:$A,0)),0) -> 86 | D14: =B14+C14 -> 187 | E14: =IFERROR(INDEX(Facebook!$E:$E,MATCH($A14,Facebook!$A:$A,0)),0) -> 2 | F14: =IFERROR(INDEX(Instagram!$E:$E,MATCH($A14,Instagram!$A:$A,0)),0) -> 4 | G14: =E14+F14 -> 6 | H14: =IFERROR(INDEX(Website!$B:$B,MATCH($A14,Website!$A:$A,0)),0) -> 543 | I14: =IFERROR(INDEX(Airbnb!$C:$C,MATCH($A14,Airbnb!$A:$A,0)),0) -> 8 | J14: =H14+I14 -> 551 | K14: =IFERROR(INDEX(Airbnb!$D:$D,MATCH($A14,Airbnb!$A:$A,0)),0) -> 0 | L14: =IFERROR(INDEX(Airbnb!$E:$E,MATCH($A14,Airbnb!$A:$A,0)),0) -> 1 | M14: =IFERROR(INDEX(Airbnb!$G:$G,MATCH($A14,Airbnb!$A:$A,0)),0) -> 200
A15: =Facebook!A14 -> 45737 | B15: =IFERROR(INDEX(Facebook!$F:$F,MATCH($A15,Facebook!$A:$A,0)),0) -> 1164 | C15: =IFERROR(INDEX(Instagram!$F:$F,MATCH($A15,Instagram!$A:$A,0)),0) -> 418 | D15: =B15+C15 -> 1582 | E15: =IFERROR(INDEX(Facebook!$E:$E,MATCH($A15,Facebook!$A:$A,0)),0) -> 17 | F15: =IFERROR(INDEX(Instagram!$E:$E,MATCH($A15,Instagram!$A:$A,0)),0) -> 26 | G15: =E15+F15 -> 43 | H15: =IFERROR(INDEX(Website!$B:$B,MATCH($A15,Website!$A:$A,0)),0) -> 630 | I15: =IFERROR(INDEX(Airbnb!$C:$C,MATCH($A15,Airbnb!$A:$A,0)),0) -> 7 | J15: =H15+I15 -> 637 | K15: =IFERROR(INDEX(Airbnb!$D:$D,MATCH($A15,Airbnb!$A:$A,0)),0) -> 0 | L15: =IFERROR(INDEX(Airbnb!$E:$E,MATCH($A15,Airbnb!$A:$A,0)),0) -> 0 | M15: =IFERROR(INDEX(Airbnb!$G:$G,MATCH($A15,Airbnb!$A:$A,0)),0) -> 0
... A160: =Facebook!A159 -> 46752 | B160: =IFERROR(INDEX(Facebook!$F:$F,MATCH($A160,Facebook!$A:$A,0)),0) -> 0 | C160: =IFERROR(INDEX(Instagram!$F:$F,MATCH($A160,Instagram!$A:$A,0)),0) -> 0 | D160: =B160+C160 -> 0 | E160: =IFERROR(INDEX(Facebook!$E:$E,MATCH($A160,Facebook!$A:$A,0)),0) -> 0 | F160: =IFERROR(INDEX(Instagram!$E:$E,MATCH($A160,Instagram!$A:$A,0)),0) -> 0 | G160: =E160+F160 -> 0 | H160: =IFERROR(INDEX(Website!$B:$B,MATCH($A160,Website!$A:$A,0)),0) -> 0 | I160: =IFERROR(INDEX(Airbnb!$C:$C,MATCH($A160,Airbnb!$A:$A,0)),0) -> 0 | J160: =H160+I160 -> 0 | K160: =IFERROR(INDEX(Airbnb!$D:$D,MATCH($A160,Airbnb!$A:$A,0)),0) -> 0 | L160: =IFERROR(INDEX(Airbnb!$E:$E,MATCH($A160,Airbnb!$A:$A,0)),0) -> 0 | M160: =IFERROR(INDEX(Airbnb!$G:$G,MATCH($A160,Airbnb!$A:$A,0)),0) -> 0

Sheet Read Me
B2: Greenside Villas — Digital Marketing Tracker & Dashboard
B3: Cleaned, restructured, and rebuilt as an interactive workbook — ready to upload to Google Sheets.
B6: ★ FULL AUTOMATION — HOW IT WORKS (read this first) ★
B7: Every tab is pre-built through 31 Dec 2027 (157 weeks). The pale-yellow rows on Facebook, Instagram, Website, and Airbnb are already dated and already wired into every formula in the workbook — you just type your weekly numbers into the next yellow row. The moment you do, it flows automatically into: the 'Summary' tab, the 'Monthly Summary' pivot-style rollup, every KPI card on the Dashboard, and every chart (Website trend, Airbnb trend, Facebook vs Instagram trend, the funnel, and the channel-selector chart). Nothing needs to be rebuilt, re-pointed, or copied — it is all live formulas referencing full columns and a shared weekly row layout across every tab.
B8: - Why this works: Facebook, Instagram, Website, and Airbnb all use the exact same list of week-starting dates in the exact same row order, so row 45 is 'the same week' on every tab. Monthly Summary and the KPI cards use whole-column SUMIFS/SUM formulas (e.g. Facebook!$F:$F), which already include any new number you add, anywhere in that column, with zero extra setup.
B9: - If you ever need weeks beyond Dec 2027: select the last filled row on a tab, then drag its fill handle (bottom-right corner of the selection) down a few rows, or copy that row and paste it below — the date and all formulas continue automatically. Do this on Facebook, Instagram, Website, and Airbnb together to keep every tab's row-alignment intact.
B11: HOW TO USE THIS WORKBOOK
B12: 1. Start on the 'Dashboard' tab — it has KPI cards, trend charts, and a channel selector (cell C70) you can change to update the chart instantly.
B13: 2. Each channel (Facebook, Instagram, Website, Airbnb) has its own cleaned data tab — one row per week, with future weeks already built and pale-yellow so you know where to type next.
B14: 3. 'Monthly Summary' is a formula-driven pivot-style rollup: every number recalculates automatically as you fill in the raw data tabs.
B15: 4. 'Google Business' and 'Reviews' tabs are set up and ready, but no data had been logged in the original file — see Data Quality Notes below.
B16: 5. 'Tourism Context' holds Tanzania national arrival figures for benchmarking Greenside's performance against the wider market.
... B42: - An interactive channel selector (dropdown) that redraws a trend chart for whichever channel you pick.

Sheet Excel Analysis
B2: GREENSIDE VILLAS — EXCEL ANALYTICS (Growth, Engagement & Funnel Modeling)
B4: Built on top of the live Monthly Summary tab — all figures below are formulas, so they update automatically as new weekly data is entered.
B6: Month | C6: FB Reach | D6: FB Reach MoM % | E6: IG Reach | F6: IG Reach MoM % | G6: Website Visitors | H6: Website MoM % | I6: FB Engagement Rate % | J6: IG Engagement Rate % | K6: Airbnb Views | L6: Airbnb Bookings | M6: Booking Conv. Rate % | N6: Airbnb Revenue ($) | O6: Revenue / Booking ($) | P6: Occupancy % | Q6: Reach-to-Booking Efficiency
B7: ='Monthly Summary'!A4 -> Jan 2025 | C7: ='Monthly Summary'!B4 -> 12099 | D7: 0 | E7: ='Monthly Summary'!F4 -> 101015 | F7: 0 | G7: ='Monthly Summary'!J4 -> 980 | H7: 0 | I7: =IFERROR('Monthly Summary'!C4/C7,0) -> 0.16596413 | J7: =IFERROR('Monthly Summary'!G4/E7,0) -> 0.0016928179 | K7: ='Monthly Summary'!M4 -> 56 | L7: ='Monthly Summary'!O4 -> 0 | M7: =IFERROR(L7/K7,0) -> 0 | N7: ='Monthly Summary'!P4 -> 0 | O7: =IFERROR(N7/L7,0) -> 0 | P7: ='Monthly Summary'!Q4 -> 0 | Q7: =IFERROR((C7+E7)/L7,0) -> 0
B8: ='Monthly Summary'!A5 -> Feb 2025 | C8: ='Monthly Summary'!B5 -> 283 | D8: =IFERROR((C8-C7)/C7,0) -> -0.97660964 | E8: ='Monthly Summary'!F5 -> 628 | F8: =IFERROR((E8-E7)/E7,0) -> -0.9937831 | G8: ='Monthly Summary'!J5 -> 1480 | H8: =IFERROR((G8-G7)/G7,0) -> 0.51020408 | I8: =IFERROR('Monthly Summary'!C5/C8,0) -> 0.042402827 | J8: =IFERROR('Monthly Summary'!G5/E8,0) -> 0.0095541401 | K8: ='Monthly Summary'!M5 -> 36 | L8: ='Monthly Summary'!O5 -> 0 | M8: =IFERROR(L8/K8,0) -> 0 | N8: ='Monthly Summary'!P5 -> 0 | O8: =IFERROR(N8/L8,0) -> 0 | P8: ='Monthly Summary'!Q5 -> 0 | Q8: =IFERROR((C8+E8)/L8,0) -> 0
B9: ='Monthly Summary'!A6 -> Mar 2025 | C9: ='Monthly Summary'!B6 -> 2562 | D9: =IFERROR((C9-C8)/C8,0) -> 8.0530035 | E9: ='Monthly Summary'!F6 -> 647 | F9: =IFERROR((E9-E8)/E8,0) -> 0.030254777 | G9: ='Monthly Summary'!J6 -> 2453 | H9: =IFERROR((G9-G8)/G8,0) -> 0.65743243 | I9: =IFERROR('Monthly Summary'!C6/C9,0) -> 0.012099922 | J9: =IFERROR('Monthly Summary'!G6/E9,0) -> 0.058732612 | K9: ='Monthly Summary'!M6 -> 31 | L9: ='Monthly Summary'!O6 -> 1 | M9: =IFERROR(L9/K9,0) -> 0.032258065 | N9: ='Monthly Summary'!P6 -> 200 | O9: =IFERROR(N9/L9,0) -> 200 | P9: ='Monthly Summary'!Q6 -> 0.25 | Q9: =IFERROR((C9+E9)/L9,0) -> 3209
B10: ='Monthly Summary'!A7 -> Apr 2025 | C10: ='Monthly Summary'!B7 -> 3542 | D10: =IFERROR((C10-C9)/C9,0) -> 0.38251366 | E10: ='Monthly Summary'!F7 -> 594 | F10: =IFERROR((E10-E9)/E9,0) -> -0.081916538 | G10: ='Monthly Summary'!J7 -> 4590 | H10: =IFERROR((G10-G9)/G9,0) -> 0.87117815 | I10: =IFERROR('Monthly Summary'!C7/C10,0) -> 0.071710898 | J10: =IFERROR('Monthly Summary'!G7/E10,0) -> 0.38888889 | K10: ='Monthly Summary'!M7 -> 41 | L10: ='Monthly Summary'!O7 -> 1 | M10: =IFERROR(L10/K10,0) -> 0.024390244 | N10: ='Monthly Summary'!P7 -> 226 | O10: =IFERROR(N10/L10,0) -> 226 | P10: ='Monthly Summary'!Q7 -> 0.11061947 | Q10: =IFERROR((C10+E10)/L10,0) -> 4136
B11: ='Monthly Summary'!A8 -> May 2025 | C11: ='Monthly Summary'!B8 -> 1572 | D11: =IFERROR((C11-C10)/C10,0) -> -0.55618295 | E11: ='Monthly Summary'!F8 -> 610 | F11: =IFERROR((E11-E10)/E10,0) -> 0.026936027 | G11: ='Monthly Summary'!J8 -> 9814 | H11: =IFERROR((G11-G10)/G10,0) -> 1.1381264 | I11: =IFERROR('Monthly Summary'!C8/C11,0) -> 0.047073791 | J11: =IFERROR('Monthly Summary'!G8/E11,0) -> 0.060655738 | K11: ='Monthly Summary'!M8 -> 51 | L11: ='Monthly Summary'!O8 -> 0 | M11: =IFERROR(L11/K11,0) -> 0 | N11: ='Monthly Summary'!P8 -> 0 | O11: =IFERROR(N11/L11,0) -> 0 | P11: ='Monthly Summary'!Q8 -> 0 | Q11: =IFERROR((C11+E11)/L11,0) -> 0
B12: ='Monthly Summary'!A9 -> Jun 2025 | C12: ='Monthly Summary'!B9 -> 195 | D12: =IFERROR((C12-C11)/C11,0) -> -0.8759542 | E12: ='Monthly Summary'!F9 -> 327 | F12: =IFERROR((E12-E11)/E11,0) -> -0.46393443 | G12: ='Monthly Summary'!J9 -> 9195 | H12: =IFERROR((G12-G11)/G11,0) -> -0.063073161 | I12: =IFERROR('Monthly Summary'!C9/C12,0) -> 0.37435897 | J12: =IFERROR('Monthly Summary'!G9/E12,0) -> 0.17125382 | K12: ='Monthly Summary'!M9 -> 18 | L12: ='Monthly Summary'!O9 -> 0 | M12: =IFERROR(L12/K12,0) -> 0 | N12: ='Monthly Summary'!P9 -> 0 | O12: =IFERROR(N12/L12,0) -> 0 | P12: ='Monthly Summary'!Q9 -> 0 | Q12: =IFERROR((C12+E12)/L12,0) -> 0
B13: ='Monthly Summary'!A10 -> Jul 2025 | C13: ='Monthly Summary'!B10 -> 132 | D13: =IFERROR((C13-C12)/C12,0) -> -0.32307692 | E13: ='Monthly Summary'!F10 -> 183 | F13: =IFERROR((E13-E12)/E12,0) -> -0.44036697 | G13: ='Monthly Summary'!J10 -> 9622 | H13: =IFERROR((G13-G12)/G12,0) -> 0.046438282 | I13: =IFERROR('Monthly Summary'!C10/C13,0) -> 0.99242424 | J13: =IFERROR('Monthly Summary'!G10/E13,0) -> 0.25136612 | K13: ='Monthly Summary'!M10 -> 45 | L13: ='Monthly Summary'!O10 -> 2 | M13: =IFERROR(L13/K13,0) -> 0.044444444 | N13: ='Monthly Summary'!P10 -> 772 | O13: =IFERROR(N13/L13,0) -> 386 | P13: ='Monthly Summary'!Q10 -> 0.19436364 | Q13: =IFERROR((C13+E13)/L13,0) -> 157.5
B14: ='Monthly Summary'!A11 -> Aug 2025 | C14: ='Monthly Summary'!B11 -> 103 | D14: =IFERROR((C14-C13)/C13,0) -> -0.21969697 | E14: ='Monthly Summary'!F11 -> 131 | F14: =IFERROR((E14-E13)/E13,0) -> -0.28415301 | G14: ='Monthly Summary'!J11 -> 12527 | H14: =IFERROR((G14-G13)/G13,0) -> 0.30191228 | I14: =IFERROR('Monthly Summary'!C11/C14,0) -> 1.3495146 | J14: =IFERROR('Monthly Summary'!G11/E14,0) -> 2.3282443 | K14: ='Monthly Summary'!M11 -> 51 | L14: ='Monthly Summary'!O11 -> 1 | M14: =IFERROR(L14/K14,0) -> 0.019607843 | N14: ='Monthly Summary'!P11 -> 891 | O14: =IFERROR(N14/L14,0) -> 891 | P14: ='Monthly Summary'!Q11 -> 0.067340067 | Q14: =IFERROR((C14+E14)/L14,0) -> 234
B15: ='Monthly Summary'!A12 -> Sep 2025 | C15: ='Monthly Summary'!B12 -> 48 | D15: =IFERROR((C15-C14)/C14,0) -> -0.53398058 | E15: ='Monthly Summary'!F12 -> 489 | F15: =IFERROR((E15-E14)/E14,0) -> 2.7328244 | G15: ='Monthly Summary'!J12 -> 10244 | H15: =IFERROR((G15-G14)/G14,0) -> -0.18224635 | I15: =IFERROR('Monthly Summary'!C12/C15,0) -> 2.625 | J15: =IFERROR('Monthly Summary'!G12/E15,0) -> 0.1390593 | K15: ='Monthly Summary'!M12 -> 29 | L15: ='Monthly Summary'!O12 -> 0 | M15: =IFERROR(L15/K15,0) -> 0 | N15: ='Monthly Summary'!P12 -> 0 | O15: =IFERROR(N15/L15,0) -> 0 | P15: ='Monthly Summary'!Q12 -> 0 | Q15: =IFERROR((C15+E15)/L15,0) -> 0
B16: ='Monthly Summary'!A13 -> Oct 2025 | C16: ='Monthly Summary'!B13 -> 226 | D16: =IFERROR((C16-C15)/C15,0) -> 3.7083333 | E16: ='Monthly Summary'!F13 -> 643 | F16: =IFERROR((E16-E15)/E15,0) -> 0.31492843 | G16: ='Monthly Summary'!J13 -> 13080 | H16: =IFERROR((G16-G15)/G15,0) -> 0.27684498 | I16: =IFERROR('Monthly Summary'!C13/C16,0) -> 0.24336283 | J16: =IFERROR('Monthly Summary'!G13/E16,0) -> 0.10108865 | K16: ='Monthly Summary'!M13 -> 37 | L16: ='Monthly Summary'!O13 -> 1 | M16: =IFERROR(L16/K16,0) -> 0.027027027 | N16: ='Monthly Summary'!P13 -> 226 | O16: =IFERROR(N16/L16,0) -> 226 | P16: ='Monthly Summary'!Q13 -> 0.088495575 | Q16: =IFERROR((C16+E16)/L16,0) -> 869
B17: ='Monthly Summary'!A14 -> Nov 2025 | C17: ='Monthly Summary'!B14 -> 384 | D17: =IFERROR((C17-C16)/C16,0) -> 0.69911504 | E17: ='Monthly Summary'!F14 -> 497 | F17: =IFERROR((E17-E16)/E16,0) -> -0.22706065 | G17: ='Monthly Summary'!J14 -> 10297 | H17: =IFERROR((G17-G16)/G16,0) -> -0.21276758 | I17: =IFERROR('Monthly Summary'!C14/C17,0) -> 0.059895833 | J17: =IFERROR('Monthly Summary'!G14/E17,0) -> 0.24144869 | K17: ='Monthly Summary'!M14 -> 45 | L17: ='Monthly Summary'!O14 -> 0 | M17: =IFERROR(L17/K17,0) -> 0 | N17: ='Monthly Summary'!P14 -> 0 | O17: =IFERROR(N17/L17,0) -> 0 | P17: ='Monthly Summary'!Q14 -> 0 | Q17: =IFERROR((C17+E17)/L17,0) -> 0
B18: ='Monthly Summary'!A15 -> Dec 2025 | C18: ='Monthly Summary'!B15 -> 130 | D18: =IFERROR((C18-C17)/C17,0) -> -0.66145833 | E18: ='Monthly Summary'!F15 -> 154 | F18: =IFERROR((E18-E17)/E17,0) -> -0.69014085 | G18: ='Monthly Summary'!J15 -> 10498 | H18: =IFERROR((G18-G17)/G17,0) -> 0.019520249 | I18: =IFERROR('Monthly Summary'!C15/C18,0) -> 0.13076923 | J18: =IFERROR('Monthly Summary'!G15/E18,0) -> 0.85714286 | K18: ='Monthly Summary'!M15 -> 60 | L18: ='Monthly Summary'!O15 -> 0 | M18: =IFERROR(L18/K18,0) -> 0 | N18: ='Monthly Summary'!P15 -> 0 | O18: =IFERROR(N18/L18,0) -> 0 | P18: ='Monthly Summary'!Q15 -> 0 | Q18: =IFERROR((C18+E18)/L18,0) -> 0
B19: ='Monthly Summary'!A16 -> Jan 2026 | C19: ='Monthly Summary'!B16 -> 123 | D19: =IFERROR((C19-C18)/C18,0) -> -0.053846154 | E19: ='Monthly Summary'!F16 -> 155 | F19: =IFERROR((E19-E18)/E18,0) -> 0.0064935065 | G19: ='Monthly Summary'!J16 -> 13190 | H19: =IFERROR((G19-G18)/G18,0) -> 0.2564298 | I19: =IFERROR('Monthly Summary'!C16/C19,0) -> 0.12195122 | J19: =IFERROR('Monthly Summary'!G16/E19,0) -> 0.67741935 | K19: ='Monthly Summary'!M16 -> 60 | L19: ='Monthly Summary'!O16 -> 1 | M19: =IFERROR(L19/K19,0) -> 0.016666667 | N19: ='Monthly Summary'!P16 -> 361 | O19: =IFERROR(N19/L19,0) -> 361 | P19: ='Monthly Summary'!Q16 -> 0.055401662 | Q19: =IFERROR((C19+E19)/L19,0) -> 278
... B43: ='Monthly Summary'!A40 -> 0 | C43: ='Monthly Summary'!B40 -> 0 | D43: =IFERROR((C43-C42)/C42,0) -> 0 | E43: ='Monthly Summary'!F40 -> 0 | F43: =IFERROR((E43-E42)/E42,0) -> 0 | G43: ='Monthly Summary'!J40 -> 0 | H43: =IFERROR((G43-G42)/G42,0) -> 0 | I43: =IFERROR('Monthly Summary'!C40/C43,0) -> 0 | J43: =IFERROR('Monthly Summary'!G40/E43,0) -> 0 | K43: ='Monthly Summary'!M40 -> 0 | L43: ='Monthly Summary'!O40 -> 0 | M43: =IFERROR(L43/K43,0) -> 0 | N43: ='Monthly Summary'!P40 -> 0 | O43: =IFERROR(N43/L43,0) -> 0 | P43: ='Monthly Summary'!Q40 -> 0 | Q43: =IFERROR((C43+E43)/L43,0) -> 0
B46: PERFORMANCE HIGHLIGHTS (auto-calculated)
B48: Best Revenue Month | E48: Best Revenue Value
B49: =INDEX(B7:B43,MATCH(MAX(N7:N43),N7:N43,0)) -> Aug 2025 | E49: =MAX(N7:N43) -> 891
B50: Best FB Reach Month | E50: Best FB Reach Value
B51: =INDEX(B7:B43,MATCH(MAX(C7:C43),C7:C43,0)) -> Jan 2025 | E51: =MAX(C7:C43) -> 12099
B52: Total Airbnb Bookings (all time) | E52: Total Airbnb Revenue (all time)
B53: =SUM(L7:L43) -> 9 | E53: =SUM(N7:N43) -> 3198
B54: Avg. Booking Conversion Rate | E54: Avg. FB Engagement Rate
B55: =AVERAGE(M7:M43) -> 0.0058514059 | E55: =AVERAGE(I7:I43) -> 0.23435767
B56: Avg. IG Engagement Rate | E56: Avg. Revenue per Booking
B57: =AVERAGE(J7:J43) -> 0.26992217 | E57: =IFERROR(SUM(N7:N43)/SUM(L7:L43),0) -> 355.33333
B61: TRENDS

Sheet Facebook
A1: Facebook — Weekly Tracking (cleaned, with 77 future weeks pre-built and ready to fill — just type new numbers in, everything downstream updates automatically)
A2: Date | B2: Followers/Visitors | C2: New Followers/Visitors | D2: Posts/Updates | E2: Engagements (Likes/Comments/Shares) | F2: Reach | G2: Impressions | H2: Clicks | I2: Conversions | J2: Facebook Reviews | K2: Notes/Observations
A3: 45660 | B3: 2200 | C3: 0 | D3: 0 | E3: 11 | F3: 219 | G3: 219 | H3: 0 | I3: 0 | K3: we must boost our post to increase, reach and potential sales
A4: 45667 | B4: 2200 | C4: 0 | D4: 1 | E4: 9 | F4: 198 | G4: 207 | H4: 0 | I4: 0
A5: 45674 | B5: 2200 | C5: 0 | D5: 2 | E5: 9 | F5: 199 | G5: 208 | H5: 0 | I5: 0
A6: 45681 | B6: 2200 | C6: 0 | D6: 1 | E6: 688 | F6: 2783 | G6: 3471 | H6: 0 | I6: 0
A7: 45688 | B7: 2200 | C7: 0 | D7: 0 | E7: 1291 | F7: 8700 | G7: 9990 | H7: 0 | I7: 0
A8: 45695 | B8: 2200 | C8: 0 | D8: 0 | E8: 4 | F8: 147 | G8: 151 | H8: 0 | I8: 0
A9: 45702 | B9: 2200 | C9: 0 | D9: 0 | E9: 2 | F9: 100 | G9: 102 | H9: 0 | I9: 0
A10: 45709 | B10: 2200 | C10: 0 | D10: 0 | E10: 4 | F10: 26 | G10: 30 | H10: 0 | I10: 0
A11: 45716 | B11: 2250 | C11: 50 | D11: 0 | E11: 2 | F11: 10 | G11: 12 | H11: 0 | I11: 0
A12: 45723 | B12: 2250 | C12: 0 | D12: 0 | E12: 3 | F12: 5 | G12: 8 | H12: 0 | I12: 0
A13: 45730 | B13: 2250 | C13: 0 | D13: 3 | E13: 2 | F13: 101 | G13: 103 | H13: 0 | I13: 0
A14: 45737 | B14: 2250 | C14: 0 | D14: 2 | E14: 17 | F14: 1164 | G14: 1181 | H14: 0 | I14: 0
A15: 45744 | B15: 2250 | C15: 0 | D15: 2 | E15: 9 | F15: 1292 | G15: 1301 | H15: 0 | I15: 0
... A82: 46213 | B82: 2417 | C82: 3 | D82: 0 | E82: 11 | F82: 14 | G82: 25 | H82: 0 | I82: 0
A83: 46220
A84: 46227
A85: 46234
A86: 46241
A87: 46248
A88: 46255
A89: 46262
A90: 46269
A91: 46276
A92: 46283
A93: 46290
A94: 46297
... A159: 46752

Sheet Instagram
A1: Instagram — Weekly Tracking (cleaned, with 80 future weeks pre-built and ready to fill — just type new numbers in, everything downstream updates automatically)
A2: Date | B2: Followers/Visitors | C2: New Followers/Visitors | D2: Posts/Updates | E2: Engagements (Likes/Comments/Shares) | F2: Reach | G2: IMPRESSION | H2: Clicks | I2: Conversions | J2: Notes/Observations
A3: 45660 | B3: 100 | C3: 0 | D3: 1 | E3: 6 | F3: 157 | G3: 163 | H3: 12 | I3: 0 | J3: when we must boost our post to oncrease our reach and potential bookings
A4: 45667 | B4: 110 | C4: 10 | D4: 1 | E4: 6 | F4: 42 | G4: 48 | H4: 22 | I4: 0
A5: 45674 | B5: 115 | C5: 5 | D5: 1 | E5: 6 | F5: 36 | G5: 42 | H5: 19 | I5: 0
A6: 45681 | B6: 118 | C6: 3 | D6: 1 | E6: 7 | F6: 280 | G6: 287 | H6: 29 | I6: 0
A7: 45688 | B7: 120 | C7: 2 | D7: 0 | E7: 146 | F7: 100500 | G7: 10646 | H7: 285 | I7: 0
A8: 45695 | B8: 130 | C8: 10 | D8: 1 | E8: 3 | F8: 359 | G8: 362 | H8: 16 | I8: 0
A9: 45702 | B9: 135 | C9: 5 | D9: 1 | E9: 1 | F9: 158 | G9: 159 | H9: 8 | I9: 0
A10: 45709 | B10: 138 | C10: 3 | D10: 0 | E10: 1 | F10: 73 | G10: 74 | H10: 12 | I10: 0
A11: 45716 | B11: 140 | C11: 2 | D11: 0 | E11: 1 | F11: 38 | G11: 39 | H11: 5 | I11: 0
A12: 45723 | B12: 142 | C12: 2 | D12: 0 | E12: 1 | F12: 30 | G12: 31 | H12: 7 | I12: 0
A13: 45730 | B13: 143 | C13: 1 | D13: 1 | E13: 4 | F13: 86 | G13: 90 | H13: 0 | I13: 0
A14: 45737 | B14: 144 | C14: 1 | D14: 2 | E14: 26 | F14: 418 | G14: 444 | H14: 0 | I14: 0
A15: 45744 | B15: 146 | C15: 2 | D15: 2 | E15: 7 | F15: 113 | G15: 120 | H15: 0 | I15: 0
... A79: 46192 | B79: 233 | C79: 3 | D79: 0 | E79: 40 | F79: 55 | G79: 95 | H79: 0 | I79: 0
A80: 46199
A81: 46206
A82: 46213
A83: 46220
A84: 46227
A85: 46234
A86: 46241
A87: 46248
A88: 46255
A89: 46262
A90: 46269
A91: 46276
... A159: 46752

Sheet Website
A1: Website — Weekly Tracking (cleaned, with 80 future weeks pre-built and ready to fill — just type new numbers in, everything downstream updates automatically)
A2: Date | B2: Visitors | C2: Page Views | D2: Bounce Rate% | E2: Average Session Duration(min) | F2: Conversions | G2: Notes/Observations | H2: New Page Views
A3: 45660 | B3: 120 | C3: 356 | D3: 0.33707865 | E3: 2 | F3: 0 | H3: 0
A4: 45667 | B4: 180 | C4: 434 | D4: 0.41474654 | E4: 1.5 | F4: 0 | H4: 78
A5: 45674 | B5: 200 | C5: 524 | D5: 0.38167939 | E5: 1.2 | F5: 0 | H5: 90
A6: 45681 | B6: 230 | C6: 682 | D6: 0.3372434 | E6: 2.1 | F6: 0 | H6: 158
A7: 45688 | B7: 250 | C7: 752 | D7: 0.33244681 | E7: 1.6 | F7: 0 | H7: 70
A8: 45695 | B8: 280 | C8: 872 | D8: 0.32110092 | E8: 1.2 | F8: 0 | H8: 120
A9: 45702 | B9: 350 | C9: 953 | D9: 0.36726128 | E9: 1.32 | F9: 0 | H9: 81
A10: 45709 | B10: 400 | C10: 1103 | D10: 0.36264733 | E10: 1.24 | F10: 0 | H10: 150
A11: 45716 | B11: 450 | C11: 1234 | D11: 0.36466775 | E11: 1.16 | F11: 0 | H11: 131
A12: 45723 | B12: 550 | C12: 1572 | D12: 0.34987277 | E12: 1.08 | F12: 0 | H12: 338
A13: 45730 | B13: 543 | C13: 1592 | D13: 0.3410804 | E13: 1 | F13: 0 | H13: 20
A14: 45737 | B14: 630 | C14: 1782 | D14: 0.35353535 | E14: 1.9 | F14: 0 | H14: 190
... A79: 46192 | B79: 3210 | C79: 7826 | D79: 0.41017122 | E79: 0.41017122 | F79: 0 | H79: 68
A80: 46199
A81: 46206
A82: 46213
A83: 46220
A84: 46227
A85: 46234
A86: 46241
A87: 46248
A88: 46255
A89: 46262
A90: 46269
A91: 46276
... A159: 46752

Sheet Airbnb
A1: Airbnb — Weekly Tracking (cleaned, with 80 future weeks pre-built and ready to fill — just type new numbers in, everything downstream updates automatically)
A2: Date | B2: Listing Name | C2: views | D2: inquires | E2: bookings | F2: Nights Booked | G2: Revenue | H2: occupancy rate(%) | I2: conversion Rate
A3: 45660 | B3: GREEN SIDE VILLAS | C3: 11 | D3: 0 | E3: 0 | F3: 0 | G3: 0 | H3: 0 | I3: 0
A4: 45667 | B4: GREEN SIDE VILLAS | C4: 12 | D4: 0 | E4: 0 | F4: 0 | G4: 0 | H4: 0 | I4: 0
A5: 45674 | B5: GREEN SIDE VILLAS | C5: 10 | D5: 0 | E5: 0 | F5: 0 | G5: 0 | H5: 0 | I5: 0
A6: 45681 | B6: GREEN SIDE VILLAS | C6: 12 | D6: 0 | E6: 0 | F6: 0 | G6: 0 | H6: 0 | I6: 0
A7: 45688 | B7: GREEN SIDE VILLAS | C7: 11 | D7: 0 | E7: 0 | F7: 0 | G7: 0 | H7: 0 | I7: 0
A8: 45695 | B8: GREEN SIDE VILLAS | C8: 12 | D8: 0 | E8: 0 | F8: 0 | G8: 0 | H8: 0 | I8: 0
A9: 45702 | B9: GREEN SIDE VILLAS | C9: 10 | D9: 1 | E9: 0 | F9: 0 | G9: 0 | H9: 0 | I9: 0
A10: 45709 | B10: GREEN SIDE VILLAS | C10: 9 | D10: 0 | E10: 0 | F10: 0 | G10: 0 | H10: 0 | I10: 0
A11: 45716 | B11: GREEN SIDE VILLAS | C11: 5 | D11: 0 | E11: 0 | F11: 0 | G11: 0 | H11: 0 | I11: 0
A12: 45723 | B12: GREEN SIDE VILLAS | C12: 7 | D12: 0 | E12: 0 | F12: 0 | G12: 0 | H12: 0 | I12: 0
A13: 45730 | B13: GREEN SIDE VILLAS | C13: 8 | D13: 0 | E13: 1 | F13: 2 | G13: 200 | H13: 1 | I13: 12.5
A14: 45737 | B14: GREEN SIDE VILLAS | C14: 7 | D14: 0 | E14: 0 | F14: 0 | G14: 0 | H14: 0 | I14: 0
... A79: 46192 | B79: GREEN SIDE VILLAS | C79: 12 | D79: 0 | E79: 0 | F79: 0 | G79: 0 | H79: 0 | I79: 0
A80: 46199 | B80: GREEN SIDE VILLAS
A81: 46206 | B81: GREEN SIDE VILLAS
A82: 46213 | B82: GREEN SIDE VILLAS
A83: 46220 | B83: GREEN SIDE VILLAS
A84: 46227 | B84: GREEN SIDE VILLAS
A85: 46234 | B85: GREEN SIDE VILLAS
A86: 46241 | B86: GREEN SIDE VILLAS
A87: 46248 | B87: GREEN SIDE VILLAS
A88: 46255 | B88: GREEN SIDE VILLAS
A89: 46262 | B89: GREEN SIDE VILLAS
A90: 46269 | B90: GREEN SIDE VILLAS
A91: 46276 | B91: GREEN SIDE VILLAS
... A159: 46752 | B159: GREEN SIDE VILLAS

Sheet Google Business
A1: Google Business Profile — Template (no historical data was logged in the source file)
A2: Week | B2: Business Profile Views | C2: Searches Showing Business Profile | D2: Chat Clicks from Business Profile | E2: Directions Requested | F2: Website Clicks | G2: Booking Clicks | H2: Google Reviews (new) | I2: Average Stars of New Reviews
A3: 46220
A4: 46227
A5: 46234
A6: 46241
A7: 46248
A8: 46255
A9: 46262
A10: 46269
A11: 46276
A12: 46283
A13: 46290
A14: 46297

Sheet Reviews
A1: Reviews — Template (no reviews had been logged in the source file)
A2: Date | B2: Source (Facebook / Google / Feedback Form / Airbnb) | C2: Overall Stars | D2: Reviewer Comment

Sheet Tourism Context
A1: Tanzania Tourist Arrivals — Market Context
A2: Year | B2: Tourist Arrivals (Million) | C2: Notes
A3: Year | B3: Tourist Arrivals (Million) | C3: Notes
A4: 2016 | B4: 1.284
A5: 2017 | B5: 1.327
A6: 2018 | B6: 1.505
A7: 2019 | B7: 1.527 | C7: Pre-COVID peak
A8: 2020 | B8: 0.62 | C8: COVID impact
A9: 2021 | B9: 0.923 | C9: Partial recovery
A10: 2022 | B10: 1.455 | C10: Rebound
A11: 2023 | B11: 1.808 | C11: Surpassed 2019
A12: 2024 | B12: 1.76 | C12: Full-year estimate, based on Jan–Aug (~1.2m)
A13: 2025 | B13: 2 | C13: Planning assumption

Sheet Monthly Summary
A1: Monthly Summary — Pivot-Style Rollup (live formulas, recalculates automatically)
A3: Month | B3: FB Reach | C3: FB Engagement | D3: FB Clicks | E3: FB Conversions | F3: IG Reach | G3: IG Engagement | H3: IG Clicks | I3: IG Conversions | J3: Website Visitors | K3: Website Page Views | L3: Website Conversions | M3: Airbnb Views | N3: Airbnb Inquiries | O3: Airbnb Bookings | P3: Airbnb Revenue ($) | Q3: Airbnb Avg Occupancy %
A4: Jan 2025 | B4: =SUMIFS(Facebook!$F:$F,Facebook!$A:$A,">="&DATE(2025,1,1),Facebook!$A:$A,"<="&DATE(2025,1,31)) -> 12099 | C4: =SUMIFS(Facebook!$E:$E,Facebook!$A:$A,">="&DATE(2025,1,1),Facebook!$A:$A,"<="&DATE(2025,1,31)) -> 2008 | D4: =SUMIFS(Facebook!$H:$H,Facebook!$A:$A,">="&DATE(2025,1,1),Facebook!$A:$A,"<="&DATE(2025,1,31)) -> 0 | E4: =SUMIFS(Facebook!$I:$I,Facebook!$A:$A,">="&DATE(2025,1,1),Facebook!$A:$A,"<="&DATE(2025,1,31)) -> 0 | F4: =SUMIFS(Instagram!$F:$F,Instagram!$A:$A,">="&DATE(2025,1,1),Instagram!$A:$A,"<="&DATE(2025,1,31)) -> 101015 | G4: =SUMIFS(Instagram!$E:$E,Instagram!$A:$A,">="&DATE(2025,1,1),Instagram!$A:$A,"<="&DATE(2025,1,31)) -> 171 | H4: =SUMIFS(Instagram!$H:$H,Instagram!$A:$A,">="&DATE(2025,1,1),Instagram!$A:$A,"<="&DATE(2025,1,31)) -> 367 | I4: =SUMIFS(Instagram!$I:$I,Instagram!$A:$A,">="&DATE(2025,1,1),Instagram!$A:$A,"<="&DATE(2025,1,31)) -> 0 | J4: =SUMIFS(Website!$B:$B,Website!$A:$A,">="&DATE(2025,1,1),Website!$A:$A,"<="&DATE(2025,1,31)) -> 980 | K4: =SUMIFS(Website!$C:$C,Website!$A:$A,">="&DATE(2025,1,1),Website!$A:$A,"<="&DATE(2025,1,31)) -> 2748 | L4: =SUMIFS(Website!$F:$F,Website!$A:$A,">="&DATE(2025,1,1),Website!$A:$A,"<="&DATE(2025,1,31)) -> 0 | M4: =SUMIFS(Airbnb!$C:$C,Airbnb!$A:$A,">="&DATE(2025,1,1),Airbnb!$A:$A,"<="&DATE(2025,1,31)) -> 56 | N4: =SUMIFS(Airbnb!$D:$D,Airbnb!$A:$A,">="&DATE(2025,1,1),Airbnb!$A:$A,"<="&DATE(2025,1,31)) -> 0 | O4: =SUMIFS(Airbnb!$E:$E,Airbnb!$A:$A,">="&DATE(2025,1,1),Airbnb!$A:$A,"<="&DATE(2025,1,31)) -> 0 | P4: =SUMIFS(Airbnb!$G:$G,Airbnb!$A:$A,">="&DATE(2025,1,1),Airbnb!$A:$A,"<="&DATE(2025,1,31)) -> 0 | Q4: =IFERROR(AVERAGEIFS(Airbnb!$H:$H,Airbnb!$A:$A,">="&DATE(2025,1,1),Airbnb!$A:$A,"<="&DATE(2025,1,31)),0) -> 0
A5: Feb 2025 | B5: =SUMIFS(Facebook!$F:$F,Facebook!$A:$A,">="&DATE(2025,2,1),Facebook!$A:$A,"<="&DATE(2025,2,28)) -> 283 | C5: =SUMIFS(Facebook!$E:$E,Facebook!$A:$A,">="&DATE(2025,2,1),Facebook!$A:$A,"<="&DATE(2025,2,28)) -> 12 | D5: =SUMIFS(Facebook!$H:$H,Facebook!$A:$A,">="&DATE(2025,2,1),Facebook!$A:$A,"<="&DATE(2025,2,28)) -> 0 | E5: =SUMIFS(Facebook!$I:$I,Facebook!$A:$A,">="&DATE(2025,2,1),Facebook!$A:$A,"<="&DATE(2025,2,28)) -> 0 | F5: =SUMIFS(Instagram!$F:$F,Instagram!$A:$A,">="&DATE(2025,2,1),Instagram!$A:$A,"<="&DATE(2025,2,28)) -> 628 | G5: =SUMIFS(Instagram!$E:$E,Instagram!$A:$A,">="&DATE(2025,2,1),Instagram!$A:$A,"<="&DATE(2025,2,28)) -> 6 | H5: =SUMIFS(Instagram!$H:$H,Instagram!$A:$A,">="&DATE(2025,2,1),Instagram!$A:$A,"<="&DATE(2025,2,28)) -> 41 | I5: =SUMIFS(Instagram!$I:$I,Instagram!$A:$A,">="&DATE(2025,2,1),Instagram!$A:$A,"<="&DATE(2025,2,28)) -> 0 | J5: =SUMIFS(Website!$B:$B,Website!$A:$A,">="&DATE(2025,2,1),Website!$A:$A,"<="&DATE(2025,2,28)) -> 1480 | K5: =SUMIFS(Website!$C:$C,Website!$A:$A,">="&DATE(2025,2,1),Website!$A:$A,"<="&DATE(2025,2,28)) -> 4162 | L5: =SUMIFS(Website!$F:$F,Website!$A:$A,">="&DATE(2025,2,1),Website!$A:$A,"<="&DATE(2025,2,28)) -> 0 | M5: =SUMIFS(Airbnb!$C:$C,Airbnb!$A:$A,">="&DATE(2025,2,1),Airbnb!$A:$A,"<="&DATE(2025,2,28)) -> 36 | N5: =SUMIFS(Airbnb!$D:$D,Airbnb!$A:$A,">="&DATE(2025,2,1),Airbnb!$A:$A,"<="&DATE(2025,2,28)) -> 1 | O5: =SUMIFS(Airbnb!$E:$E,Airbnb!$A:$A,">="&DATE(2025,2,1),Airbnb!$A:$A,"<="&DATE(2025,2,28)) -> 0 | P5: =SUMIFS(Airbnb!$G:$G,Airbnb!$A:$A,">="&DATE(2025,2,1),Airbnb!$A:$A,"<="&DATE(2025,2,28)) -> 0 | Q5: =IFERROR(AVERAGEIFS(Airbnb!$H:$H,Airbnb!$A:$A,">="&DATE(2025,2,1),Airbnb!$A:$A,"<="&DATE(2025,2,28)),0) -> 0
A6: Mar 2025 | B6: =SUMIFS(Facebook!$F:$F,Facebook!$A:$A,">="&DATE(2025,3,1),Facebook!$A:$A,"<="&DATE(2025,3,31)) -> 2562 | C6: =SUMIFS(Facebook!$E:$E,Facebook!$A:$A,">="&DATE(2025,3,1),Facebook!$A:$A,"<="&DATE(2025,3,31)) -> 31 | D6: =SUMIFS(Facebook!$H:$H,Facebook!$A:$A,">="&DATE(2025,3,1),Facebook!$A:$A,"<="&DATE(2025,3,31)) -> 0 | E6: =SUMIFS(Facebook!$I:$I,Facebook!$A:$A,">="&DATE(2025,3,1),Facebook!$A:$A,"<="&DATE(2025,3,31)) -> 0 | F6: =SUMIFS(Instagram!$F:$F,Instagram!$A:$A,">="&DATE(2025,3,1),Instagram!$A:$A,"<="&DATE(2025,3,31)) -> 647 | G6: =SUMIFS(Instagram!$E:$E,Instagram!$A:$A,">="&DATE(2025,3,1),Instagram!$A:$A,"<="&DATE(2025,3,31)) -> 38 | H6: =SUMIFS(Instagram!$H:$H,Instagram!$A:$A,">="&DATE(2025,3,1),Instagram!$A:$A,"<="&DATE(2025,3,31)) -> 7 | I6: =SUMIFS(Instagram!$I:$I,Instagram!$A:$A,">="&DATE(2025,3,1),Instagram!$A:$A,"<="&DATE(2025,3,31)) -> 0 | J6: =SUMIFS(Website!$B:$B,Website!$A:$A,">="&DATE(2025,3,1),Website!$A:$A,"<="&DATE(2025,3,31)) -> 2453 | K6: =SUMIFS(Website!$C:$C,Website!$A:$A,">="&DATE(2025,3,1),Website!$A:$A,"<="&DATE(2025,3,31)) -> 6931 | L6: =SUMIFS(Website!$F:$F,Website!$A:$A,">="&DATE(2025,3,1),Website!$A:$A,"<="&DATE(2025,3,31)) -> 0 | M6: =SUMIFS(Airbnb!$C:$C,Airbnb!$A:$A,">="&DATE(2025,3,1),Airbnb!$A:$A,"<="&DATE(2025,3,31)) -> 31 | N6: =SUMIFS(Airbnb!$D:$D,Airbnb!$A:$A,">="&DATE(2025,3,1),Airbnb!$A:$A,"<="&DATE(2025,3,31)) -> 0 | O6: =SUMIFS(Airbnb!$E:$E,Airbnb!$A:$A,">="&DATE(2025,3,1),Airbnb!$A:$A,"<="&DATE(2025,3,31)) -> 1 | P6: =SUMIFS(Airbnb!$G:$G,Airbnb!$A:$A,">="&DATE(2025,3,1),Airbnb!$A:$A,"<="&DATE(2025,3,31)) -> 200 | Q6: =IFERROR(AVERAGEIFS(Airbnb!$H:$H,Airbnb!$A:$A,">="&DATE(2025,3,1),Airbnb!$A:$A,"<="&DATE(2025,3,31)),0) -> 0.25
A7: Apr 2025 | B7: =SUMIFS(Facebook!$F:$F,Facebook!$A:$A,">="&DATE(2025,4,1),Facebook!$A:$A,"<="&DATE(2025,4,30)) -> 3542 | C7: =SUMIFS(Facebook!$E:$E,Facebook!$A:$A,">="&DATE(2025,4,1),Facebook!$A:$A,"<="&DATE(2025,4,30)) -> 254 | D7: =SUMIFS(Facebook!$H:$H,Facebook!$A:$A,">="&DATE(2025,4,1),Facebook!$A:$A,"<="&DATE(2025,4,30)) -> 0 | E7: =SUMIFS(Facebook!$I:$I,Facebook!$A:$A,">="&DATE(2025,4,1),Facebook!$A:$A,"<="&DATE(2025,4,30)) -> 0 | F7: =SUMIFS(Instagram!$F:$F,Instagram!$A:$A,">="&DATE(2025,4,1),Instagram!$A:$A,"<="&DATE(2025,4,30)) -> 594 | G7: =SUMIFS(Instagram!$E:$E,Instagram!$A:$A,">="&DATE(2025,4,1),Instagram!$A:$A,"<="&DATE(2025,4,30)) -> 231 | H7: =SUMIFS(Instagram!$H:$H,Instagram!$A:$A,">="&DATE(2025,4,1),Instagram!$A:$A,"<="&DATE(2025,4,30)) -> 7 | I7: =SUMIFS(Instagram!$I:$I,Instagram!$A:$A,">="&DATE(2025,4,1),Instagram!$A:$A,"<="&DATE(2025,4,30)) -> 1 | J7: =SUMIFS(Website!$B:$B,Website!$A:$A,">="&DATE(2025,4,1),Website!$A:$A,"<="&DATE(2025,4,30)) -> 4590 | K7: =SUMIFS(Website!$C:$C,Website!$A:$A,">="&DATE(2025,4,1),Website!$A:$A,"<="&DATE(2025,4,30)) -> 9083 | L7: =SUMIFS(Website!$F:$F,Website!$A:$A,">="&DATE(2025,4,1),Website!$A:$A,"<="&DATE(2025,4,30)) -> 0 | M7: =SUMIFS(Airbnb!$C:$C,Airbnb!$A:$A,">="&DATE(2025,4,1),Airbnb!$A:$A,"<="&DATE(2025,4,30)) -> 41 | N7: =SUMIFS(Airbnb!$D:$D,Airbnb!$A:$A,">="&DATE(2025,4,1),Airbnb!$A:$A,"<="&DATE(2025,4,30)) -> 1 | O7: =SUMIFS(Airbnb!$E:$E,Airbnb!$A:$A,">="&DATE(2025,4,1),Airbnb!$A:$A,"<="&DATE(2025,4,30)) -> 1 | P7: =SUMIFS(Airbnb!$G:$G,Airbnb!$A:$A,">="&DATE(2025,4,1),Airbnb!$A:$A,"<="&DATE(2025,4,30)) -> 226 | Q7: =IFERROR(AVERAGEIFS(Airbnb!$H:$H,Airbnb!$A:$A,">="&DATE(2025,4,1),Airbnb!$A:$A,"<="&DATE(2025,4,30)),0) -> 0.11061947
A8: May 2025 | B8: =SUMIFS(Facebook!$F:$F,Facebook!$A:$A,">="&DATE(2025,5,1),Facebook!$A:$A,"<="&DATE(2025,5,31)) -> 1572 | C8: =SUMIFS(Facebook!$E:$E,Facebook!$A:$A,">="&DATE(2025,5,1),Facebook!$A:$A,"<="&DATE(2025,5,31)) -> 74 | D8: =SUMIFS(Facebook!$H:$H,Facebook!$A:$A,">="&DATE(2025,5,1),Facebook!$A:$A,"<="&DATE(2025,5,31)) -> 0 | E8: =SUMIFS(Facebook!$I:$I,Facebook!$A:$A,">="&DATE(2025,5,1),Facebook!$A:$A,"<="&DATE(2025,5,31)) -> 0 | F8: =SUMIFS(Instagram!$F:$F,Instagram!$A:$A,">="&DATE(2025,5,1),Instagram!$A:$A,"<="&DATE(2025,5,31)) -> 610 | G8: =SUMIFS(Instagram!$E:$E,Instagram!$A:$A,">="&DATE(2025,5,1),Instagram!$A:$A,"<="&DATE(2025,5,31)) -> 37 | H8: =SUMIFS(Instagram!$H:$H,Instagram!$A:$A,">="&DATE(2025,5,1),Instagram!$A:$A,"<="&DATE(2025,5,31)) -> 0 | I8: =SUMIFS(Instagram!$I:$I,Instagram!$A:$A,">="&DATE(2025,5,1),Instagram!$A:$A,"<="&DATE(2025,5,31)) -> 1 | J8: =SUMIFS(Website!$B:$B,Website!$A:$A,">="&DATE(2025,5,1),Website!$A:$A,"<="&DATE(2025,5,31)) -> 9814 | K8: =SUMIFS(Website!$C:$C,Website!$A:$A,">="&DATE(2025,5,1),Website!$A:$A,"<="&DATE(2025,5,31)) -> 15815 | L8: =SUMIFS(Website!$F:$F,Website!$A:$A,">="&DATE(2025,5,1),Website!$A:$A,"<="&DATE(2025,5,31)) -> 0 | M8: =SUMIFS(Airbnb!$C:$C,Airbnb!$A:$A,">="&DATE(2025,5,1),Airbnb!$A:$A,"<="&DATE(2025,5,31)) -> 51 | N8: =SUMIFS(Airbnb!$D:$D,Airbnb!$A:$A,">="&DATE(2025,5,1),Airbnb!$A:$A,"<="&DATE(2025,5,31)) -> 0 | O8: =SUMIFS(Airbnb!$E:$E,Airbnb!$A:$A,">="&DATE(2025,5,1),Airbnb!$A:$A,"<="&DATE(2025,5,31)) -> 0 | P8: =SUMIFS(Airbnb!$G:$G,Airbnb!$A:$A,">="&DATE(2025,5,1),Airbnb!$A:$A,"<="&DATE(2025,5,31)) -> 0 | Q8: =IFERROR(AVERAGEIFS(Airbnb!$H:$H,Airbnb!$A:$A,">="&DATE(2025,5,1),Airbnb!$A:$A,"<="&DATE(2025,5,31)),0) -> 0
A9: Jun 2025 | B9: =SUMIFS(Facebook!$F:$F,Facebook!$A:$A,">="&DATE(2025,6,1),Facebook!$A:$A,"<="&DATE(2025,6,30)) -> 195 | C9: =SUMIFS(Facebook!$E:$E,Facebook!$A:$A,">="&DATE(2025,6,1),Facebook!$A:$A,"<="&DATE(2025,6,30)) -> 73 | D9: =SUMIFS(Facebook!$H:$H,Facebook!$A:$A,">="&DATE(2025,6,1),Facebook!$A:$A,"<="&DATE(2025,6,30)) -> 0 | E9: =SUMIFS(Facebook!$I:$I,Facebook!$A:$A,">="&DATE(2025,6,1),Facebook!$A:$A,"<="&DATE(2025,6,30)) -> 0 | F9: =SUMIFS(Instagram!$F:$F,Instagram!$A:$A,">="&DATE(2025,6,1),Instagram!$A:$A,"<="&DATE(2025,6,30)) -> 327 | G9: =SUMIFS(Instagram!$E:$E,Instagram!$A:$A,">="&DATE(2025,6,1),Instagram!$A:$A,"<="&DATE(2025,6,30)) -> 56 | H9: =SUMIFS(Instagram!$H:$H,Instagram!$A:$A,">="&DATE(2025,6,1),Instagram!$A:$A,"<="&DATE(2025,6,30)) -> 0 | I9: =SUMIFS(Instagram!$I:$I,Instagram!$A:$A,">="&DATE(2025,6,1),Instagram!$A:$A,"<="&DATE(2025,6,30)) -> 0 | J9: =SUMIFS(Website!$B:$B,Website!$A:$A,">="&DATE(2025,6,1),Website!$A:$A,"<="&DATE(2025,6,30)) -> 9195 | K9: =SUMIFS(Website!$C:$C,Website!$A:$A,">="&DATE(2025,6,1),Website!$A:$A,"<="&DATE(2025,6,30)) -> 17044 | L9: =SUMIFS(Website!$F:$F,Website!$A:$A,">="&DATE(2025,6,1),Website!$A:$A,"<="&DATE(2025,6,30)) -> 0 | M9: =SUMIFS(Airbnb!$C:$C,Airbnb!$A:$A,">="&DATE(2025,6,1),Airbnb!$A:$A,"<="&DATE(2025,6,30)) -> 18 | N9: =SUMIFS(Airbnb!$D:$D,Airbnb!$A:$A,">="&DATE(2025,6,1),Airbnb!$A:$A,"<="&DATE(2025,6,30)) -> 0 | O9: =SUMIFS(Airbnb!$E:$E,Airbnb!$A:$A,">="&DATE(2025,6,1),Airbnb!$A:$A,"<="&DATE(2025,6,30)) -> 0 | P9: =SUMIFS(Airbnb!$G:$G,Airbnb!$A:$A,">="&DATE(2025,6,1),Airbnb!$A:$A,"<="&DATE(2025,6,30)) -> 0 | Q9: =IFERROR(AVERAGEIFS(Airbnb!$H:$H,Airbnb!$A:$A,">="&DATE(2025,6,1),Airbnb!$A:$A,"<="&DATE(2025,6,30)),0) -> 0
A10: Jul 2025 | B10: =SUMIFS(Facebook!$F:$F,Facebook!$A:$A,">="&DATE(2025,7,1),Facebook!$A:$A,"<="&DATE(2025,7,31)) -> 132 | C10: =SUMIFS(Facebook!$E:$E,Facebook!$A:$A,">="&DATE(2025,7,1),Facebook!$A:$A,"<="&DATE(2025,7,31)) -> 131 | D10: =SUMIFS(Facebook!$H:$H,Facebook!$A:$A,">="&DATE(2025,7,1),Facebook!$A:$A,"<="&DATE(2025,7,31)) -> 0 | E10: =SUMIFS(Facebook!$I:$I,Facebook!$A:$A,">="&DATE(2025,7,1),Facebook!$A:$A,"<="&DATE(2025,7,31)) -> 0 | F10: =SUMIFS(Instagram!$F:$F,Instagram!$A:$A,">="&DATE(2025,7,1),Instagram!$A:$A,"<="&DATE(2025,7,31)) -> 183 | G10: =SUMIFS(Instagram!$E:$E,Instagram!$A:$A,">="&DATE(2025,7,1),Instagram!$A:$A,"<="&DATE(2025,7,31)) -> 46 | H10: =SUMIFS(Instagram!$H:$H,Instagram!$A:$A,">="&DATE(2025,7,1),Instagram!$A:$A,"<="&DATE(2025,7,31)) -> 0 | I10: =SUMIFS(Instagram!$I:$I,Instagram!$A:$A,">="&DATE(2025,7,1),Instagram!$A:$A,"<="&DATE(2025,7,31)) -> 0 | J10: =SUMIFS(Website!$B:$B,Website!$A:$A,">="&DATE(2025,7,1),Website!$A:$A,"<="&DATE(2025,7,31)) -> 9622 | K10: =SUMIFS(Website!$C:$C,Website!$A:$A,">="&DATE(2025,7,1),Website!$A:$A,"<="&DATE(2025,7,31)) -> 19378 | L10: =SUMIFS(Website!$F:$F,Website!$A:$A,">="&DATE(2025,7,1),Website!$A:$A,"<="&DATE(2025,7,31)) -> 0 | M10: =SUMIFS(Airbnb!$C:$C,Airbnb!$A:$A,">="&DATE(2025,7,1),Airbnb!$A:$A,"<="&DATE(2025,7,31)) -> 45 | N10: =SUMIFS(Airbnb!$D:$D,Airbnb!$A:$A,">="&DATE(2025,7,1),Airbnb!$A:$A,"<="&DATE(2025,7,31)) -> 2 | O10: =SUMIFS(Airbnb!$E:$E,Airbnb!$A:$A,">="&DATE(2025,7,1),Airbnb!$A:$A,"<="&DATE(2025,7,31)) -> 2 | P10: =SUMIFS(Airbnb!$G:$G,Airbnb!$A:$A,">="&DATE(2025,7,1),Airbnb!$A:$A,"<="&DATE(2025,7,31)) -> 772 | Q10: =IFERROR(AVERAGEIFS(Airbnb!$H:$H,Airbnb!$A:$A,">="&DATE(2025,7,1),Airbnb!$A:$A,"<="&DATE(2025,7,31)),0) -> 0.19436364
A11: Aug 2025 | B11: =SUMIFS(Facebook!$F:$F,Facebook!$A:$A,">="&DATE(2025,8,1),Facebook!$A:$A,"<="&DATE(2025,8,31)) -> 103 | C11: =SUMIFS(Facebook!$E:$E,Facebook!$A:$A,">="&DATE(2025,8,1),Facebook!$A:$A,"<="&DATE(2025,8,31)) -> 139 | D11: =SUMIFS(Facebook!$H:$H,Facebook!$A:$A,">="&DATE(2025,8,1),Facebook!$A:$A,"<="&DATE(2025,8,31)) -> 0 | E11: =SUMIFS(Facebook!$I:$I,Facebook!$A:$A,">="&DATE(2025,8,1),Facebook!$A:$A,"<="&DATE(2025,8,31)) -> 0 | F11: =SUMIFS(Instagram!$F:$F,Instagram!$A:$A,">="&DATE(2025,8,1),Instagram!$A:$A,"<="&DATE(2025,8,31)) -> 131 | G11: =SUMIFS(Instagram!$E:$E,Instagram!$A:$A,">="&DATE(2025,8,1),Instagram!$A:$A,"<="&DATE(2025,8,31)) -> 305 | H11: =SUMIFS(Instagram!$H:$H,Instagram!$A:$A,">="&DATE(2025,8,1),Instagram!$A:$A,"<="&DATE(2025,8,31)) -> 0 | I11: =SUMIFS(Instagram!$I:$I,Instagram!$A:$A,">="&DATE(2025,8,1),Instagram!$A:$A,"<="&DATE(2025,8,31)) -> 0 | J11: =SUMIFS(Website!$B:$B,Website!$A:$A,">="&DATE(2025,8,1),Website!$A:$A,"<="&DATE(2025,8,31)) -> 12527 | K11: =SUMIFS(Website!$C:$C,Website!$A:$A,">="&DATE(2025,8,1),Website!$A:$A,"<="&DATE(2025,8,31)) -> 27472 | L11: =SUMIFS(Website!$F:$F,Website!$A:$A,">="&DATE(2025,8,1),Website!$A:$A,"<="&DATE(2025,8,31)) -> 0 | M11: =SUMIFS(Airbnb!$C:$C,Airbnb!$A:$A,">="&DATE(2025,8,1),Airbnb!$A:$A,"<="&DATE(2025,8,31)) -> 51 | N11: =SUMIFS(Airbnb!$D:$D,Airbnb!$A:$A,">="&DATE(2025,8,1),Airbnb!$A:$A,"<="&DATE(2025,8,31)) -> 2 | O11: =SUMIFS(Airbnb!$E:$E,Airbnb!$A:$A,">="&DATE(2025,8,1),Airbnb!$A:$A,"<="&DATE(2025,8,31)) -> 1 | P11: =SUMIFS(Airbnb!$G:$G,Airbnb!$A:$A,">="&DATE(2025,8,1),Airbnb!$A:$A,"<="&DATE(2025,8,31)) -> 891 | Q11: =IFERROR(AVERAGEIFS(Airbnb!$H:$H,Airbnb!$A:$A,">="&DATE(2025,8,1),Airbnb!$A:$A,"<="&DATE(2025,8,31)),0) -> 0.067340067
A12: Sep 2025 | B12: =SUMIFS(Facebook!$F:$F,Facebook!$A:$A,">="&DATE(2025,9,1),Facebook!$A:$A,"<="&DATE(2025,9,30)) -> 48 | C12: =SUMIFS(Facebook!$E:$E,Facebook!$A:$A,">="&DATE(2025,9,1),Facebook!$A:$A,"<="&DATE(2025,9,30)) -> 126 | D12: =SUMIFS(Facebook!$H:$H,Facebook!$A:$A,">="&DATE(2025,9,1),Facebook!$A:$A,"<="&DATE(2025,9,30)) -> 0 | E12: =SUMIFS(Facebook!$I:$I,Facebook!$A:$A,">="&DATE(2025,9,1),Facebook!$A:$A,"<="&DATE(2025,9,30)) -> 0 | F12: =SUMIFS(Instagram!$F:$F,Instagram!$A:$A,">="&DATE(2025,9,1),Instagram!$A:$A,"<="&DATE(2025,9,30)) -> 489 | G12: =SUMIFS(Instagram!$E:$E,Instagram!$A:$A,">="&DATE(2025,9,1),Instagram!$A:$A,"<="&DATE(2025,9,30)) -> 68 | H12: =SUMIFS(Instagram!$H:$H,Instagram!$A:$A,">="&DATE(2025,9,1),Instagram!$A:$A,"<="&DATE(2025,9,30)) -> 0 | I12: =SUMIFS(Instagram!$I:$I,Instagram!$A:$A,">="&DATE(2025,9,1),Instagram!$A:$A,"<="&DATE(2025,9,30)) -> 0 | J12: =SUMIFS(Website!$B:$B,Website!$A:$A,">="&DATE(2025,9,1),Website!$A:$A,"<="&DATE(2025,9,30)) -> 10244 | K12: =SUMIFS(Website!$C:$C,Website!$A:$A,">="&DATE(2025,9,1),Website!$A:$A,"<="&DATE(2025,9,30)) -> 22498 | L12: =SUMIFS(Website!$F:$F,Website!$A:$A,">="&DATE(2025,9,1),Website!$A:$A,"<="&DATE(2025,9,30)) -> 0 | M12: =SUMIFS(Airbnb!$C:$C,Airbnb!$A:$A,">="&DATE(2025,9,1),Airbnb!$A:$A,"<="&DATE(2025,9,30)) -> 29 | N12: =SUMIFS(Airbnb!$D:$D,Airbnb!$A:$A,">="&DATE(2025,9,1),Airbnb!$A:$A,"<="&DATE(2025,9,30)) -> 1 | O12: =SUMIFS(Airbnb!$E:$E,Airbnb!$A:$A,">="&DATE(2025,9,1),Airbnb!$A:$A,"<="&DATE(2025,9,30)) -> 0 | P12: =SUMIFS(Airbnb!$G:$G,Airbnb!$A:$A,">="&DATE(2025,9,1),Airbnb!$A:$A,"<="&DATE(2025,9,30)) -> 0 | Q12: =IFERROR(AVERAGEIFS(Airbnb!$H:$H,Airbnb!$A:$A,">="&DATE(2025,9,1),Airbnb!$A:$A,"<="&DATE(2025,9,30)),0) -> 0
A13: Oct 2025 | B13: =SUMIFS(Facebook!$F:$F,Facebook!$A:$A,">="&DATE(2025,10,1),Facebook!$A:$A,"<="&DATE(2025,10,31)) -> 226 | C13: =SUMIFS(Facebook!$E:$E,Facebook!$A:$A,">="&DATE(2025,10,1),Facebook!$A:$A,"<="&DATE(2025,10,31)) -> 55 | D13: =SUMIFS(Facebook!$H:$H,Facebook!$A:$A,">="&DATE(2025,10,1),Facebook!$A:$A,"<="&DATE(2025,10,31)) -> 0 | E13: =SUMIFS(Facebook!$I:$I,Facebook!$A:$A,">="&DATE(2025,10,1),Facebook!$A:$A,"<="&DATE(2025,10,31)) -> 0 | F13: =SUMIFS(Instagram!$F:$F,Instagram!$A:$A,">="&DATE(2025,10,1),Instagram!$A:$A,"<="&DATE(2025,10,31)) -> 643 | G13: =SUMIFS(Instagram!$E:$E,Instagram!$A:$A,">="&DATE(2025,10,1),Instagram!$A:$A,"<="&DATE(2025,10,31)) -> 65 | H13: =SUMIFS(Instagram!$H:$H,Instagram!$A:$A,">="&DATE(2025,10,1),Instagram!$A:$A,"<="&DATE(2025,10,31)) -> 0 | I13: =SUMIFS(Instagram!$I:$I,Instagram!$A:$A,">="&DATE(2025,10,1),Instagram!$A:$A,"<="&DATE(2025,10,31)) -> 0 | J13: =SUMIFS(Website!$B:$B,Website!$A:$A,">="&DATE(2025,10,1),Website!$A:$A,"<="&DATE(2025,10,31)) -> 13080 | K13: =SUMIFS(Website!$C:$C,Website!$A:$A,">="&DATE(2025,10,1),Website!$A:$A,"<="&DATE(2025,10,31)) -> 28617 | L13: =SUMIFS(Website!$F:$F,Website!$A:$A,">="&DATE(2025,10,1),Website!$A:$A,"<="&DATE(2025,10,31)) -> 0 | M13: =SUMIFS(Airbnb!$C:$C,Airbnb!$A:$A,">="&DATE(2025,10,1),Airbnb!$A:$A,"<="&DATE(2025,10,31)) -> 37 | N13: =SUMIFS(Airbnb!$D:$D,Airbnb!$A:$A,">="&DATE(2025,10,1),Airbnb!$A:$A,"<="&DATE(2025,10,31)) -> 1 | O13: =SUMIFS(Airbnb!$E:$E,Airbnb!$A:$A,">="&DATE(2025,10,1),Airbnb!$A:$A,"<="&DATE(2025,10,31)) -> 1 | P13: =SUMIFS(Airbnb!$G:$G,Airbnb!$A:$A,">="&DATE(2025,10,1),Airbnb!$A:$A,"<="&DATE(2025,10,31)) -> 226 | Q13: =IFERROR(AVERAGEIFS(Airbnb!$H:$H,Airbnb!$A:$A,">="&DATE(2025,10,1),Airbnb!$A:$A,"<="&DATE(2025,10,31)),0) -> 0.088495575
